Workbook

Sheet dailyActivity_merged
A1: Id | B1: ActivityDate | C1: TotalSteps | D1: TotalDistance | E1: TrackerDistance | F1: LoggedActivitiesDistance | G1: VeryActiveDistance | H1: ModeratelyActiveDistance | I1: LightActiveDistance | J1: SedentaryActiveDistance | K1: VeryActiveMinutes | L1: FairlyActiveMinutes | M1: LightlyActiveMinutes | N1: SedentaryMinutes | O1: Calories
A2: 1503960366 | B2: 42454 | C2: 11004 | D2: 7.1100001 | E2: 7.1100001 | F2: 0 | G2: 2.5699999 | H2: 0.46000001 | I2: 4.0700002 | J2: 0 | K2: 33 | L2: 12 | M2: 205 | N2: 804 | O2: 1819
A3: 1503960366 | B3: 42455 | C3: 17609 | D3: 11.55 | E3: 11.55 | F3: 0 | G3: 6.9200001 | H3: 0.73000002 | I3: 3.9100001 | J3: 0 | K3: 89 | L3: 17 | M3: 274 | N3: 588 | O3: 2154
A4: 1503960366 | B4: 42456 | C4: 12736 | D4: 8.5299997 | E4: 8.5299997 | F4: 0 | G4: 4.6599998 | H4: 0.16 | I4: 3.71 | J4: 0 | K4: 56 | L4: 5 | M4: 268 | N4: 605 | O4: 1944
A5: 1503960366 | B5: 42457 | C5: 13231 | D5: 8.9300003 | E5: 8.9300003 | F5: 0 | G5: 3.1900001 | H5: 0.79000002 | I5: 4.9499998 | J5: 0 | K5: 39 | L5: 20 | M5: 224 | N5: 1080 | O5: 1932
A6: 1503960366 | B6: 42458 | C6: 12041 | D6: 7.8499999 | E6: 7.8499999 | F6: 0 | G6: 2.1600001 | H6: 1.09 | I6: 4.6100001 | J6: 0 | K6: 28 | L6: 28 | M6: 243 | N6: 763 | O6: 1886
A7: 1503960366 | B7: 42459 | C7: 10970 | D7: 7.1599998 | E7: 7.1599998 | F7: 0 | G7: 2.3599999 | H7: 0.50999999 | I7: 4.29 | J7: 0 | K7: 30 | L7: 13 | M7: 223 | N7: 1174 | O7: 1820
A8: 1503960366 | B8: 42460 | C8: 12256 | D8: 7.8600001 | E8: 7.8600001 | F8: 0 | G8: 2.29 | H8: 0.49000001 | I8: 5.04 | J8: 0 | K8: 33 | L8: 12 | M8: 239 | N8: 820 | O8: 1889
A9: 1503960366 | B9: 42461 | C9: 12262 | D9: 7.8699999 | E9: 7.8699999 | F9: 0 | G9: 3.3199999 | H9: 0.82999998 | I9: 3.6400001 | J9: 0 | K9: 47 | L9: 21 | M9: 200 | N9: 866 | O9: 1868
A10: 1503960366 | B10: 42462 | C10: 11248 | D10: 7.25 | E10: 7.25 | F10: 0 | G10: 3 | H10: 0.44999999 | I10: 3.74 | J10: 0 | K10: 40 | L10: 11 | M10: 244 | N10: 636 | O10: 1843
A11: 1503960366 | B11: 42463 | C11: 10016 | D11: 6.3699999 | E11: 6.3699999 | F11: 0 | G11: 0.91000003 | H11: 1.28 | I11: 4.1799998 | J11: 0 | K11: 15 | L11: 30 | M11: 314 | N11: 655 | O11: 1850
A12: 1503960366 | B12: 42464 | C12: 14557 | D12: 9.8000002 | E12: 9.8000002 | F12: 0 | G12: 3.3900001 | H12: 0.69999999 | I12: 5.6900001 | J12: 0 | K12: 43 | L12: 18 | M12: 285 | N12: 757 | O12: 2030
A13: 1503960366 | B13: 42465 | C13: 14844 | D13: 9.7299995 | E13: 9.7299995 | F13: 0 | G13: 2.9400001 | H13: 0.75999999 | I13: 6.04 | J13: 0 | K13: 36 | L13: 18 | M13: 341 | N13: 736 | O13: 2083
... A458: 8877689391 | B458: 42472 | C458: 2350 | D458: 1.78 | E458: 1.78 | F458: 0 | G458: 0 | H458: 0 | I458: 1.78 | J458: 0 | K458: 0 | L458: 0 | M458: 58 | N458: 531 | O458: 938

Sheet dailyActivity
A1: Id | B1: ActivityDate | C1: TotalSteps | D1: TotalDistance | E1: TrackerDistance | F1: LoggedActivitiesDistance | G1: VeryActiveDistance | H1: ModeratelyActiveDistance | I1: LightActiveDistance | J1: SedentaryActiveDistance | K1: VeryActiveMinutes | L1: FairlyActiveMinutes | M1: LightlyActiveMinutes | N1: SedentaryMinutes | O1: Calories | P1: Sleep Hours
A2: 1503960366 | B2: 42454 | C2: 11004 | D2: 7.1100001 | E2: 7.1100001 | F2: 0 | G2: 2.5699999 | H2: 0.46000001 | I2: 4.0700002 | J2: 0 | K2: 33 | L2: 12 | M2: 205 | N2: 804 | O2: 1819 | P2: {=_xlfn.XLOOKUP(A2&B2,'[1]Daily Sleep'!$A$2:$A$468&'[1]Daily Sleep'!$B$2:$B$468,'[1]Daily Sleep'!$D$2:$D$468,"")} -> 5.85
A3: 1503960366 | B3: 42455 | C3: 17609 | D3: 11.55 | E3: 11.55 | F3: 0 | G3: 6.9200001 | H3: 0.73000002 | I3: 3.9100001 | J3: 0 | K3: 89 | L3: 17 | M3: 274 | N3: 588 | O3: 2154 | P3: {=_xlfn.XLOOKUP(A3&B3,'[1]Daily Sleep'!$A$2:$A$468&'[1]Daily Sleep'!$B$2:$B$468,'[1]Daily Sleep'!$D$2:$D$468,"")} -> 7.2833333
A4: 1503960366 | B4: 42456 | C4: 12736 | D4: 8.5299997 | E4: 8.5299997 | F4: 0 | G4: 4.6599998 | H4: 0.16 | I4: 3.71 | J4: 0 | K4: 56 | L4: 5 | M4: 268 | N4: 605 | O4: 1944 | P4: {=_xlfn.XLOOKUP(A4&B4,'[1]Daily Sleep'!$A$2:$A$468&'[1]Daily Sleep'!$B$2:$B$468,'[1]Daily Sleep'!$D$2:$D$468,"")} -> 8.05
A5: 1503960366 | B5: 42457 | C5: 13231 | D5: 8.9300003 | E5: 8.9300003 | F5: 0 | G5: 3.1900001 | H5: 0.79000002 | I5: 4.9499998 | J5: 0 | K5: 39 | L5: 20 | M5: 224 | N5: 1080 | O5: 1932 | P5: {=_xlfn.XLOOKUP(A5&B5,'[1]Daily Sleep'!$A$2:$A$468&'[1]Daily Sleep'!$B$2:$B$468,'[1]Daily Sleep'!$D$2:$D$468,"")} -> 1.2166667
A6: 1503960366 | B6: 42458 | C6: 12041 | D6: 7.8499999 | E6: 7.8499999 | F6: 0 | G6: 2.1600001 | H6: 1.09 | I6: 4.6100001 | J6: 0 | K6: 28 | L6: 28 | M6: 243 | N6: 763 | O6: 1886 | P6: {=_xlfn.XLOOKUP(A6&B6,'[1]Daily Sleep'!$A$2:$A$468&'[1]Daily Sleep'!$B$2:$B$468,'[1]Daily Sleep'!$D$2:$D$468,"")} -> 5.8166667
A7: 1503960366 | B7: 42459 | C7: 10970 | D7: 7.1599998 | E7: 7.1599998 | F7: 0 | G7: 2.3599999 | H7: 0.50999999 | I7: 4.29 | J7: 0 | K7: 30 | L7: 13 | M7: 223 | N7: 1174 | O7: 1820 | P7: {=_xlfn.XLOOKUP(A7&B7,'[1]Daily Sleep'!$A$2:$A$468&'[1]Daily Sleep'!$B$2:$B$468,'[1]Daily Sleep'!$D$2:$D$468,"")}
A8: 1503960366 | B8: 42460 | C8: 12256 | D8: 7.8600001 | E8: 7.8600001 | F8: 0 | G8: 2.29 | H8: 0.49000001 | I8: 5.04 | J8: 0 | K8: 33 | L8: 12 | M8: 239 | N8: 820 | O8: 1889 | P8: {=_xlfn.XLOOKUP(A8&B8,'[1]Daily Sleep'!$A$2:$A$468&'[1]Daily Sleep'!$B$2:$B$468,'[1]Daily Sleep'!$D$2:$D$468,"")} -> 5.1333333
A9: 1503960366 | B9: 42461 | C9: 12262 | D9: 7.8699999 | E9: 7.8699999 | F9: 0 | G9: 3.3199999 | H9: 0.82999998 | I9: 3.6400001 | J9: 0 | K9: 47 | L9: 21 | M9: 200 | N9: 866 | O9: 1868 | P9: {=_xlfn.XLOOKUP(A9&B9,'[1]Daily Sleep'!$A$2:$A$468&'[1]Daily Sleep'!$B$2:$B$468,'[1]Daily Sleep'!$D$2:$D$468,"")} -> 4.7166667
A10: 1503960366 | B10: 42462 | C10: 11248 | D10: 7.25 | E10: 7.25 | F10: 0 | G10: 3 | H10: 0.44999999 | I10: 3.74 | J10: 0 | K10: 40 | L10: 11 | M10: 244 | N10: 636 | O10: 1843 | P10: {=_xlfn.XLOOKUP(A10&B10,'[1]Daily Sleep'!$A$2:$A$468&'[1]Daily Sleep'!$B$2:$B$468,'[1]Daily Sleep'!$D$2:$D$468,"")} -> 7.3166667
A11: 1503960366 | B11: 42463 | C11: 10016 | D11: 6.3699999 | E11: 6.3699999 | F11: 0 | G11: 0.91000003 | H11: 1.28 | I11: 4.1799998 | J11: 0 | K11: 15 | L11: 30 | M11: 314 | N11: 655 | O11: 1850 | P11: {=_xlfn.XLOOKUP(A11&B11,'[1]Daily Sleep'!$A$2:$A$468&'[1]Daily Sleep'!$B$2:$B$468,'[1]Daily Sleep'!$D$2:$D$468,"")} -> 6.3166667
A12: 1503960366 | B12: 42464 | C12: 14557 | D12: 9.8000002 | E12: 9.8000002 | F12: 0 | G12: 3.3900001 | H12: 0.69999999 | I12: 5.6900001 | J12: 0 | K12: 43 | L12: 18 | M12: 285 | N12: 757 | O12: 2030 | P12: {=_xlfn.XLOOKUP(A12&B12,'[1]Daily Sleep'!$A$2:$A$468&'[1]Daily Sleep'!$B$2:$B$468,'[1]Daily Sleep'!$D$2:$D$468,"")} -> 4.9
A13: 1503960366 | B13: 42465 | C13: 14844 | D13: 9.7299995 | E13: 9.7299995 | F13: 0 | G13: 2.9400001 | H13: 0.75999999 | I13: 6.04 | J13: 0 | K13: 36 | L13: 18 | M13: 341 | N13: 736 | O13: 2083 | P13: {=_xlfn.XLOOKUP(A13&B13,'[1]Daily Sleep'!$A$2:$A$468&'[1]Daily Sleep'!$B$2:$B$468,'[1]Daily Sleep'!$D$2:$D$468,"")} -> 4.6666667
... A458: 8877689391 | B458: 42472 | C458: 2350 | D458: 1.78 | E458: 1.78 | F458: 0 | G458: 0 | H458: 0 | I458: 1.78 | J458: 0 | K458: 0 | L458: 0 | M458: 58 | N458: 531 | O458: 938 | P458: {=_xlfn.XLOOKUP(A458&B458,'[1]Daily Sleep'!$A$2:$A$468&'[1]Daily Sleep'!$B$2:$B$468,'[1]Daily Sleep'!$D$2:$D$468,"")}

Sheet Analysis
A1: Id | B1: ActivityDate | C1: TotalSteps | D1: TotalDistance | E1: TrackerDistance | F1: LoggedActivitiesDistance | G1: VeryActiveDistance | H1: ModeratelyActiveDistance | I1: LightActiveDistance | J1: SedentaryActiveDistance | K1: VeryActiveMinutes | L1: FairlyActiveMinutes | M1: LightlyActiveMinutes | N1: SedentaryMinutes | O1: Calories | P1: Sleep Hours | Q1: Day of Week | R1: Day Type
A2: 1503960366 | B2: 42454 | C2: 11004 | D2: 7.1100001 | E2: 7.1100001 | F2: 0 | G2: 2.5699999 | H2: 0.46000001 | I2: 4.0700002 | J2: 0 | K2: 33 | L2: 12 | M2: 205 | N2: 804 | O2: 1819 | P2: {=_xlfn.XLOOKUP(A2&B2,'[1]Daily Sleep'!$A$2:$A$468&'[1]Daily Sleep'!$B$2:$B$468,'[1]Daily Sleep'!$D$2:$D$468,"")} -> 5.85 | Q2: =TEXT(B2,"dddd") -> Friday | R2: =IF(OR(WEEKDAY(B3,2)=5,WEEKDAY(B3,2)=6),"Weekend","Weekday") -> Weekend
A3: 1503960366 | B3: 42455 | C3: 17609 | D3: 11.55 | E3: 11.55 | F3: 0 | G3: 6.9200001 | H3: 0.73000002 | I3: 3.9100001 | J3: 0 | K3: 89 | L3: 17 | M3: 274 | N3: 588 | O3: 2154 | P3: {=_xlfn.XLOOKUP(A3&B3,'[1]Daily Sleep'!$A$2:$A$468&'[1]Daily Sleep'!$B$2:$B$468,'[1]Daily Sleep'!$D$2:$D$468,"")} -> 7.2833333 | Q3: =TEXT(B3,"dddd") -> Saturday | R3: =IF(OR(WEEKDAY(B4,2)=5,WEEKDAY(B4,2)=6),"Weekend","Weekday") -> Weekday
A4: 1503960366 | B4: 42456 | C4: 12736 | D4: 8.5299997 | E4: 8.5299997 | F4: 0 | G4: 4.6599998 | H4: 0.16 | I4: 3.71 | J4: 0 | K4: 56 | L4: 5 | M4: 268 | N4: 605 | O4: 1944 | P4: {=_xlfn.XLOOKUP(A4&B4,'[1]Daily Sleep'!$A$2:$A$468&'[1]Daily Sleep'!$B$2:$B$468,'[1]Daily Sleep'!$D$2:$D$468,"")} -> 8.05 | Q4: =TEXT(B4,"dddd") -> Sunday | R4: =IF(OR(WEEKDAY(B5,2)=5,WEEKDAY(B5,2)=6),"Weekend","Weekday") -> Weekday
A5: 1503960366 | B5: 42457 | C5: 13231 | D5: 8.9300003 | E5: 8.9300003 | F5: 0 | G5: 3.1900001 | H5: 0.79000002 | I5: 4.9499998 | J5: 0 | K5: 39 | L5: 20 | M5: 224 | N5: 1080 | O5: 1932 | P5: {=_xlfn.XLOOKUP(A5&B5,'[1]Daily Sleep'!$A$2:$A$468&'[1]Daily Sleep'!$B$2:$B$468,'[1]Daily Sleep'!$D$2:$D$468,"")} -> 1.2166667 | Q5: =TEXT(B5,"dddd") -> Monday | R5: =IF(OR(WEEKDAY(B6,2)=5,WEEKDAY(B6,2)=6),"Weekend","Weekday") -> Weekday
A6: 1503960366 | B6: 42458 | C6: 12041 | D6: 7.8499999 | E6: 7.8499999 | F6: 0 | G6: 2.1600001 | H6: 1.09 | I6: 4.6100001 | J6: 0 | K6: 28 | L6: 28 | M6: 243 | N6: 763 | O6: 1886 | P6: {=_xlfn.XLOOKUP(A6&B6,'[1]Daily Sleep'!$A$2:$A$468&'[1]Daily Sleep'!$B$2:$B$468,'[1]Daily Sleep'!$D$2:$D$468,"")} -> 5.8166667 | Q6: =TEXT(B6,"dddd") -> Tuesday | R6: =IF(OR(WEEKDAY(B7,2)=5,WEEKDAY(B7,2)=6),"Weekend","Weekday") -> Weekday
A7: 1503960366 | B7: 42459 | C7: 10970 | D7: 7.1599998 | E7: 7.1599998 | F7: 0 | G7: 2.3599999 | H7: 0.50999999 | I7: 4.29 | J7: 0 | K7: 30 | L7: 13 | M7: 223 | N7: 1174 | O7: 1820 | P7: {=_xlfn.XLOOKUP(A7&B7,'[1]Daily Sleep'!$A$2:$A$468&'[1]Daily Sleep'!$B$2:$B$468,'[1]Daily Sleep'!$D$2:$D$468,"")} | Q7: =TEXT(B7,"dddd") -> Wednesday | R7: =IF(OR(WEEKDAY(B8,2)=5,WEEKDAY(B8,2)=6),"Weekend","Weekday") -> Weekday
A8: 1503960366 | B8: 42460 | C8: 12256 | D8: 7.8600001 | E8: 7.8600001 | F8: 0 | G8: 2.29 | H8: 0.49000001 | I8: 5.04 | J8: 0 | K8: 33 | L8: 12 | M8: 239 | N8: 820 | O8: 1889 | P8: {=_xlfn.XLOOKUP(A8&B8,'[1]Daily Sleep'!$A$2:$A$468&'[1]Daily Sleep'!$B$2:$B$468,'[1]Daily Sleep'!$D$2:$D$468,"")} -> 5.1333333 | Q8: =TEXT(B8,"dddd") -> Thursday | R8: =IF(OR(WEEKDAY(B9,2)=5,WEEKDAY(B9,2)=6),"Weekend","Weekday") -> Weekend
A9: 1503960366 | B9: 42461 | C9: 12262 | D9: 7.8699999 | E9: 7.8699999 | F9: 0 | G9: 3.3199999 | H9: 0.82999998 | I9: 3.6400001 | J9: 0 | K9: 47 | L9: 21 | M9: 200 | N9: 866 | O9: 1868 | P9: {=_xlfn.XLOOKUP(A9&B9,'[1]Daily Sleep'!$A$2:$A$468&'[1]Daily Sleep'!$B$2:$B$468,'[1]Daily Sleep'!$D$2:$D$468,"")} -> 4.7166667 | Q9: =TEXT(B9,"dddd") -> Friday | R9: =IF(OR(WEEKDAY(B10,2)=5,WEEKDAY(B10,2)=6),"Weekend","Weekday") -> Weekend
A10: 1503960366 | B10: 42462 | C10: 11248 | D10: 7.25 | E10: 7.25 | F10: 0 | G10: 3 | H10: 0.44999999 | I10: 3.74 | J10: 0 | K10: 40 | L10: 11 | M10: 244 | N10: 636 | O10: 1843 | P10: {=_xlfn.XLOOKUP(A10&B10,'[1]Daily Sleep'!$A$2:$A$468&'[1]Daily Sleep'!$B$2:$B$468,'[1]Daily Sleep'!$D$2:$D$468,"")} -> 7.3166667 | Q10: =TEXT(B10,"dddd") -> Saturday | R10: =IF(OR(WEEKDAY(B11,2)=5,WEEKDAY(B11,2)=6),"Weekend","Weekday") -> Weekday
A11: 1503960366 | B11: 42463 | C11: 10016 | D11: 6.3699999 | E11: 6.3699999 | F11: 0 | G11: 0.91000003 | H11: 1.28 | I11: 4.1799998 | J11: 0 | K11: 15 | L11: 30 | M11: 314 | N11: 655 | O11: 1850 | P11: {=_xlfn.XLOOKUP(A11&B11,'[1]Daily Sleep'!$A$2:$A$468&'[1]Daily Sleep'!$B$2:$B$468,'[1]Daily Sleep'!$D$2:$D$468,"")} -> 6.3166667 | Q11: =TEXT(B11,"dddd") -> Sunday | R11: =IF(OR(WEEKDAY(B12,2)=5,WEEKDAY(B12,2)=6),"Weekend","Weekday") -> Weekday
A12: 1503960366 | B12: 42464 | C12: 14557 | D12: 9.8000002 | E12: 9.8000002 | F12: 0 | G12: 3.3900001 | H12: 0.69999999 | I12: 5.6900001 | J12: 0 | K12: 43 | L12: 18 | M12: 285 | N12: 757 | O12: 2030 | P12: {=_xlfn.XLOOKUP(A12&B12,'[1]Daily Sleep'!$A$2:$A$468&'[1]Daily Sleep'!$B$2:$B$468,'[1]Daily Sleep'!$D$2:$D$468,"")} -> 4.9 | Q12: =TEXT(B12,"dddd") -> Monday | R12: =IF(OR(WEEKDAY(B13,2)=5,WEEKDAY(B13,2)=6),"Weekend","Weekday") -> Weekday
A13: 1503960366 | B13: 42465 | C13: 14844 | D13: 9.7299995 | E13: 9.7299995 | F13: 0 | G13: 2.9400001 | H13: 0.75999999 | I13: 6.04 | J13: 0 | K13: 36 | L13: 18 | M13: 341 | N13: 736 | O13: 2083 | P13: {=_xlfn.XLOOKUP(A13&B13,'[1]Daily Sleep'!$A$2:$A$468&'[1]Daily Sleep'!$B$2:$B$468,'[1]Daily Sleep'!$D$2:$D$468,"")} -> 4.6666667 | Q13: =TEXT(B13,"dddd") -> Tuesday | R13: =IF(OR(WEEKDAY(B14,2)=5,WEEKDAY(B14,2)=6),"Weekend","Weekday") -> Weekday
... A85: 2022484408 | B85: 42472 | C85: 6717 | D85: 4.7199998 | E85: 4.7199998 | F85: 0 | G85: 3.23 | H85: 0.22 | I85: 1.27 | J85: 0 | K85: 41 | L85: 5 | M85: 67 | N85: 551 | O85: 1140 | P85: {=_xlfn.XLOOKUP(A85&B85,'[1]Daily Sleep'!$A$2:$A$468&'[1]Daily Sleep'!$B$2:$B$468,'[1]Daily Sleep'!$D$2:$D$468,"")} | Q85: =TEXT(B85,"dddd") -> Tuesday | R85: =IF(OR(WEEKDAY(B86,2)=5,WEEKDAY(B86,2)=6),"Weekend","Weekday") -> Weekend
A86: 2026352035 | B86: 42461 | C86: 2605 | D86: 1.62 | E86: 1.62 | F86: 0 | G86: 0 | H86: 0 | I86: 1.62 | J86: 0 | K86: 0 | L86: 0 | M86: 166 | N86: 729 | O86: 1407 | P86: {=_xlfn.XLOOKUP(A86&B86,'[1]Daily Sleep'!$A$2:$A$468&'[1]Daily Sleep'!$B$2:$B$468,'[1]Daily Sleep'!$D$2:$D$468,"")} -> 8.5666667 | Q86: =TEXT(B86,"dddd") -> Friday | R86: =IF(OR(WEEKDAY(B87,2)=5,WEEKDAY(B87,2)=6),"Weekend","Weekday") -> Weekend | T86: =CORREL(P2:P443,C2:C443) -> -0.17978997
A87: 2026352035 | B87: 42462 | C87: 1229 | D87: 0.75999999 | E87: 0.75999999 | F87: 0 | G87: 0 | H87: 0 | I87: 0.75999999 | J87: 0 | K87: 0 | L87: 0 | M87: 69 | N87: 795 | O87: 1237 | P87: {=_xlfn.XLOOKUP(A87&B87,'[1]Daily Sleep'!$A$2:$A$468&'[1]Daily Sleep'!$B$2:$B$468,'[1]Daily Sleep'!$D$2:$D$468,"")} -> 8.8 | Q87: =TEXT(B87,"dddd") -> Saturday | R87: =IF(OR(WEEKDAY(B88,2)=5,WEEKDAY(B88,2)=6),"Weekend","Weekday") -> Weekday
A88: 2026352035 | B88: 42463 | C88: 2308 | D88: 1.4299999 | E88: 1.4299999 | F88: 0 | G88: 0 | H88: 0 | I88: 1.4299999 | J88: 0 | K88: 0 | L88: 0 | M88: 115 | N88: 720 | O88: 1330 | P88: {=_xlfn.XLOOKUP(A88&B88,'[1]Daily Sleep'!$A$2:$A$468&'[1]Daily Sleep'!$B$2:$B$468,'[1]Daily Sleep'!$D$2:$D$468,"")} -> 8.9 | Q88: =TEXT(B88,"dddd") -> Sunday | R88: =IF(OR(WEEKDAY(B89,2)=5,WEEKDAY(B89,2)=6),"Weekend","Weekday") -> Weekday
A89: 2026352035 | B89: 42464 | C89: 6679 | D89: 4.1399999 | E89: 4.1399999 | F89: 0 | G89: 0 | H89: 0 | I89: 4.1399999 | J89: 0 | K89: 0 | L89: 0 | M89: 263 | N89: 644 | O89: 1583 | P89: {=_xlfn.XLOOKUP(A89&B89,'[1]Daily Sleep'!$A$2:$A$468&'[1]Daily Sleep'!$B$2:$B$468,'[1]Daily Sleep'!$D$2:$D$468,"")} -> 8.2166667 | Q89: =TEXT(B89,"dddd") -> Monday | R89: =IF(OR(WEEKDAY(B90,2)=5,WEEKDAY(B90,2)=6),"Weekend","Weekday") -> Weekday
A90: 2026352035 | B90: 42465 | C90: 5645 | D90: 3.5 | E90: 3.5 | F90: 0 | G90: 0 | H90: 0 | I90: 3.5 | J90: 0 | K90: 0 | L90: 0 | M90: 248 | N90: 621 | O90: 1538 | P90: {=_xlfn.XLOOKUP(A90&B90,'[1]Daily Sleep'!$A$2:$A$468&'[1]Daily Sleep'!$B$2:$B$468,'[1]Daily Sleep'!$D$2:$D$468,"")} -> 8.85 | Q90: =TEXT(B90,"dddd") -> Tuesday | R90: =IF(OR(WEEKDAY(B91,2)=5,WEEKDAY(B91,2)=6),"Weekend","Weekday") -> Weekday
A91: 2026352035 | B91: 42466 | C91: 3180 | D91: 1.97 | E91: 1.97 | F91: 0 | G91: 0 | H91: 0 | I91: 1.97 | J91: 0 | K91: 0 | L91: 0 | M91: 185 | N91: 738 | O91: 1421 | P91: {=_xlfn.XLOOKUP(A91&B91,'[1]Daily Sleep'!$A$2:$A$468&'[1]Daily Sleep'!$B$2:$B$468,'[1]Daily Sleep'!$D$2:$D$468,"")} -> 7.75 | Q91: =TEXT(B91,"dddd") -> Wednesday | R91: =IF(OR(WEEKDAY(B92,2)=5,WEEKDAY(B92,2)=6),"Weekend","Weekday") -> Weekday
A92: 2026352035 | B92: 42467 | C92: 2767 | D92: 1.72 | E92: 1.72 | F92: 0 | G92: 0 | H92: 0 | I92: 1.72 | J92: 0 | K92: 0 | L92: 0 | M92: 170 | N92: 673 | O92: 1392 | P92: {=_xlfn.XLOOKUP(A92&B92,'[1]Daily Sleep'!$A$2:$A$468&'[1]Daily Sleep'!$B$2:$B$468,'[1]Daily Sleep'!$D$2:$D$468,"")} -> 9 | Q92: =TEXT(B92,"dddd") -> Thursday | R92: =IF(OR(WEEKDAY(B93,2)=5,WEEKDAY(B93,2)=6),"Weekend","Weekday") -> Weekend
A93: 2026352035 | B93: 42468 | C93: 3762 | D93: 2.3299999 | E93: 2.3299999 | F93: 0 | G93: 0 | H93: 0 | I93: 2.3299999 | J93: 0 | K93: 0 | L93: 0 | M93: 173 | N93: 719 | O93: 1425 | P93: {=_xlfn.XLOOKUP(A93&B93,'[1]Daily Sleep'!$A$2:$A$468&'[1]Daily Sleep'!$B$2:$B$468,'[1]Daily Sleep'!$D$2:$D$468,"")} -> 8.6833333 | Q93: =TEXT(B93,"dddd") -> Friday | R93: =IF(OR(WEEKDAY(B94,2)=5,WEEKDAY(B94,2)=6),"Weekend","Weekday") -> Weekend
A94: 2026352035 | B94: 42469 | C94: 3098 | D94: 1.92 | E94: 1.92 | F94: 0 | G94: 0 | H94: 0 | I94: 1.92 | J94: 0 | K94: 0 | L94: 0 | M94: 185 | N94: 700 | O94: 1413 | P94: {=_xlfn.XLOOKUP(A94&B94,'[1]Daily Sleep'!$A$2:$A$468&'[1]Daily Sleep'!$B$2:$B$468,'[1]Daily Sleep'!$D$2:$D$468,"")} -> 8.1666667 | Q94: =TEXT(B94,"dddd") -> Saturday | R94: =IF(OR(WEEKDAY(B95,2)=5,WEEKDAY(B95,2)=6),"Weekend","Weekday") -> Weekday
A95: 2026352035 | B95: 42470 | C95: 5142 | D95: 3.1900001 | E95: 3.1900001 | F95: 0 | G95: 0 | H95: 0 | I95: 3.1900001 | J95: 0 | K95: 0 | L95: 0 | M95: 230 | N95: 654 | O95: 1515 | P95: {=_xlfn.XLOOKUP(A95&B95,'[1]Daily Sleep'!$A$2:$A$468&'[1]Daily Sleep'!$B$2:$B$468,'[1]Daily Sleep'!$D$2:$D$468,"")} -> 8.4 | Q95: =TEXT(B95,"dddd") -> Sunday | R95: =IF(OR(WEEKDAY(B96,2)=5,WEEKDAY(B96,2)=6),"Weekend","Weekday") -> Weekday
A96: 2026352035 | B96: 42471 | C96: 3279 | D96: 2.03 | E96: 2.03 | F96: 0 | G96: 0 | H96: 0 | I96: 2.03 | J96: 0 | K96: 0 | L96: 0 | M96: 164 | N96: 694 | O96: 1405 | P96: {=_xlfn.XLOOKUP(A96&B96,'[1]Daily Sleep'!$A$2:$A$468&'[1]Daily Sleep'!$B$2:$B$468,'[1]Daily Sleep'!$D$2:$D$468,"")} -> 9.0166667 | Q96: =TEXT(B96,"dddd") -> Monday | R96: =IF(OR(WEEKDAY(B97,2)=5,WEEKDAY(B97,2)=6),"Weekend","Weekday") -> Weekday
A97: 2026352035 | B97: 42472 | C97: 1019 | D97: 0.63 | E97: 0.63 | F97: 0 | G97: 0 | H97: 0 | I97: 0.63 | J97: 0 | K97: 0 | L97: 0 | M97: 64 | N97: 223 | O97: 600 | P97: {=_xlfn.XLOOKUP(A97&B97,'[1]Daily Sleep'!$A$2:$A$468&'[1]Daily Sleep'!$B$2:$B$468,'[1]Daily Sleep'!$D$2:$D$468,"")} -> 5.6833333 | Q97: =TEXT(B97,"dddd") -> Tuesday | R97: =IF(OR(WEEKDAY(B98,2)=5,WEEKDAY(B98,2)=6),"Weekend","Weekday") -> Weekend
A98: 2320127002 | B98: 42461 | C98: 0 | D98: 0 | E98: 0 | F98: 0 | G98: 0 | H98: 0 | I98: 0 | J98: 0 | K98: 0 | L98: 0 | M98: 0 | N98: 1440 | O98: 1324 | P98: {=_xlfn.XLOOKUP(A98&B98,'[1]Daily Sleep'!$A$2:$A$468&'[1]Daily Sleep'!$B$2:$B$468,'[1]Daily Sleep'!$D$2:$D$468,"")} | Q98: =TEXT(B98,"dddd") -> Friday | R98: =IF(OR(WEEKDAY(B99,2)=5,WEEKDAY(B99,2)=6),"Weekend","Weekday") -> Weekend
... A458: 8877689391 | B458: 42472 | C458: 2350 | D458: 1.78 | E458: 1.78 | F458: 0 | G458: 0 | H458: 0 | I458: 1.78 | J458: 0 | K458: 0 | L458: 0 | M458: 58 | N458: 531 | O458: 938 | P458: {=_xlfn.XLOOKUP(A458&B458,'[1]Daily Sleep'!$A$2:$A$468&'[1]Daily Sleep'!$B$2:$B$468,'[1]Daily Sleep'!$D$2:$D$468,"")} | Q458: =TEXT(B458,"dddd") -> Tuesday | R458: =IF(OR(WEEKDAY(B459,2)=5,WEEKDAY(B459,2)=6),"Weekend","Weekday") -> Weekend

Sheet Analysis Summary
A1: Business Question 1: What are some trends in smart device usage?
A2: Analysis 1: Daily Step Count
A3: The data shows considerable variation in daily step counts. The average was 6,547 steps, while the median was 5,986 steps. Approximately 50% of recorded days fell between 1,988 and 10,198 steps. Five potential upper outliers were identified, but there was no clear evidence that they were data errors.
A6: Metric | B6: Value
A7: Average Total Steps | B7: =AVERAGE(Analysis!C2:C458) -> 6546.5624
A8: Minimum Total Steps | B8: =MIN(Analysis!C2:C458) -> 0
A9: Maximum Total Steps | B9: =MAX(Analysis!C2:C458) -> 28497
A10: Median | B10: =MEDIAN(Analysis!C2:C458) -> 5986
A12: Q1 Total Steps | B12: =_xlfn.QUARTILE.INC(Analysis!C2:C458,1) -> 1988
A13: Q3 Total Steps | B13: =_xlfn.QUARTILE.INC(Analysis!C2:C458,3) -> 10198
A14: IQR Total Steps | B14: =B13-B12 -> 8210
A16: Upper Outlier Bound | B16: =B13+1.5*B14 -> 22513
A17: Lower Outlier Bound | B17: =B12-1.5*B14 -> -10327
A19: >upper | B19: =COUNTIF(Analysis!C2:C458,">=22513") -> 5
A20: <lower | B20: =COUNTIF(Analysis!C2:C458,"<=-10327") -> 0
A22: Analysis 2: Weekday vs. Weekend Steps
A23: The analysis shows that average daily steps were higher on weekdays than on weekends. Users recorded an average of 6,866 steps on weekdays compared with 5,879 steps on weekends, representing approximately 17% more steps on weekdays.
A26: Metric | B26: Value
A27: Weekday Avg | B27: =AVERAGEIF(Analysis!R2:R458,"Weekday",Analysis!C2:C458) -> 6866.1068
A28: Weekend Avg | B28: =AVERAGEIF(Analysis!R2:R458,"Weekend",Analysis!C2:C458) -> 5879.4054
A29: Diff | B29: =B27-B28 -> 986.70139
A30: Prec | B30: =(B27-B28)/B28 -> 0.16782333
A32: Analysis 3: Steps by Day of the Week
A33: The analysis shows variation in average daily steps across the week, with Wednesday recording the highest average (7,511 steps) and Tuesday the lowest (4,915 steps). However, no consistent weekly trend was observed, as step counts varied across the different days.
A36: Metric | B36: Value
A37: Sunday | B37: =AVERAGEIF(Analysis!Q2:Q458,Analysis!Q4,Analysis!C2:C458) -> 6058.0139
A38: Monday | B38: =AVERAGEIF(Analysis!Q2:Q458,Analysis!Q5,Analysis!C2:C458) -> 7118.5882
A39: Tuesday | B39: =AVERAGEIF(Analysis!Q2:Q458,Analysis!Q6,Analysis!C2:C458) -> 4914.9178
A40: Wednesday | B40: =AVERAGEIF(Analysis!Q2:Q458,Analysis!Q7,Analysis!C2:C458) -> 7510.7083
A41: Thursday | B41: =AVERAGEIF(Analysis!Q2:Q458,Analysis!Q15,Analysis!C2:C458) -> 6847.0833
A42: Friday | B42: =AVERAGEIF(Analysis!Q2:Q458,Analysis!Q9,Analysis!C2:C458) -> 6737.5616
A43: Saturday | B43: =AVERAGEIF(Analysis!Q2:Q458,Analysis!Q10,Analysis!C2:C458) -> 7089.7733
A45: Analysis 4: Steps by Hour of the Day
A46: The analysis shows a clear daily pattern in activity levels. Average hourly steps began increasing around 6:00, remained relatively high throughout the day, and reached the highest point at 19:00 (529 steps/hour). After 20:00, activity began to decline.
A49: Metric | B49: Value | C49: Peak
A50: 0 | B50: 44.421156
A51: 1 | B51: 20.484819
A52: 2 | B52: 10.588639
A53: 3 | B53: 7.3120707
A54: 4 | B54: 9.7554028
...

Sheet Dashboard
A1: BELLABEAT USER BEHAVIOR
A3: Fitbit Smart Device Usage Analysis
